INFO:     Will watch for changes in these directories: ['/Users/kgt/Desktop/Projects/new-trackon/backend']
INFO:     Uvicorn running on http://0.0.0.0:8000 (Press CTRL+C to quit)
INFO:     Started reloader process [88621] using WatchFiles
INFO:     Started server process [88625]
INFO:     Waiting for application startup.
INFO:     Application startup complete.
INFO:     127.0.0.1:49944 - "GET /api/contacts/ HTTP/1.1" 200 OK
INFO:     127.0.0.1:50256 - "OPTIONS / HTTP/1.1" 200 OK
INFO:     127.0.0.1:50257 - "OPTIONS / HTTP/1.1" 200 OK
INFO:     127.0.0.1:50256 - "GET / HTTP/1.1" 200 OK
INFO:     127.0.0.1:50256 - "GET / HTTP/1.1" 200 OK
INFO:     127.0.0.1:50256 - "GET / HTTP/1.1" 200 OK
INFO:     127.0.0.1:50256 - "GET / HTTP/1.1" 200 OK
INFO:     127.0.0.1:50256 - "GET / HTTP/1.1" 200 OK
INFO:     127.0.0.1:50256 - "GET / HTTP/1.1" 200 OK
INFO:     127.0.0.1:50256 - "OPTIONS /api/contacts/ HTTP/1.1" 200 OK
INFO:     127.0.0.1:50261 - "GET /api/contacts/ HTTP/1.1" 200 OK
INFO:     127.0.0.1:50416 - "GET / HTTP/1.1" 200 OK
INFO:     127.0.0.1:50416 - "GET / HTTP/1.1" 200 OK
INFO:     127.0.0.1:50416 - "OPTIONS /api/fundraising/ HTTP/1.1" 200 OK
INFO:     127.0.0.1:50416 - "GET /api/fundraising/ HTTP/1.1" 404 Not Found
INFO:     127.0.0.1:50416 - "GET / HTTP/1.1" 200 OK
INFO:     127.0.0.1:50416 - "GET / HTTP/1.1" 200 OK
INFO:     127.0.0.1:50416 - "OPTIONS /api/users/ HTTP/1.1" 200 OK
INFO:     127.0.0.1:50435 - "GET /api/users/ HTTP/1.1" 404 Not Found
INFO:     127.0.0.1:50435 - "GET /api/fundraising/ HTTP/1.1" 404 Not Found
INFO:     127.0.0.1:50435 - "GET /api/contacts/ HTTP/1.1" 200 OK
INFO:     127.0.0.1:50976 - "GET /api/contacts/ HTTP/1.1" 200 OK
INFO:     127.0.0.1:53363 - "GET / HTTP/1.1" 200 OK
INFO:     127.0.0.1:53363 - "GET / HTTP/1.1" 200 OK
INFO:     127.0.0.1:53363 - "GET / HTTP/1.1" 200 OK
INFO:     127.0.0.1:53363 - "GET / HTTP/1.1" 200 OK
INFO:     127.0.0.1:53363 - "GET / HTTP/1.1" 200 OK
INFO:     127.0.0.1:53363 - "GET / HTTP/1.1" 200 OK
INFO:     127.0.0.1:53363 - "GET / HTTP/1.1" 200 OK
INFO:     127.0.0.1:53363 - "GET / HTTP/1.1" 200 OK
INFO:     127.0.0.1:53363 - "GET / HTTP/1.1" 200 OK
INFO:     127.0.0.1:53363 - "GET / HTTP/1.1" 200 OK
INFO:     127.0.0.1:54000 - "GET / HTTP/1.1" 200 OK
INFO:     127.0.0.1:54000 - "GET / HTTP/1.1" 200 OK
INFO:     127.0.0.1:54000 - "GET / HTTP/1.1" 200 OK
INFO:     127.0.0.1:54000 - "GET / HTTP/1.1" 200 OK
WARNING:  WatchFiles detected changes in 'scripts/import_data.py'. Reloading...
INFO:     Shutting down
INFO:     Waiting for application shutdown.
INFO:     Application shutdown complete.
INFO:     Finished server process [88625]
INFO:     Started server process [89177]
INFO:     Waiting for application startup.
INFO:     Application startup complete.
INFO:     127.0.0.1:60451 - "OPTIONS /api/contacts/ HTTP/1.1" 200 OK
INFO:     127.0.0.1:60451 - "GET /api/contacts/ HTTP/1.1" 200 OK
INFO:     127.0.0.1:53942 - "OPTIONS /api/fundraising/ HTTP/1.1" 200 OK
INFO:     127.0.0.1:53942 - "GET /api/fundraising/ HTTP/1.1" 404 Not Found
INFO:     127.0.0.1:53944 - "OPTIONS /api/contacts/ HTTP/1.1" 200 OK
INFO:     127.0.0.1:53944 - "GET /api/contacts/ HTTP/1.1" 200 OK
INFO:     127.0.0.1:55534 - "OPTIONS / HTTP/1.1" 200 OK
INFO:     127.0.0.1:55534 - "GET / HTTP/1.1" 200 OK
INFO:     127.0.0.1:59000 - "OPTIONS / HTTP/1.1" 200 OK
INFO:     127.0.0.1:59001 - "OPTIONS / HTTP/1.1" 200 OK
INFO:     127.0.0.1:59000 - "GET / HTTP/1.1" 200 OK
INFO:     127.0.0.1:59000 - "GET / HTTP/1.1" 200 OK
INFO:     127.0.0.1:59000 - "GET /api/contacts/ HTTP/1.1" 200 OK
WARNING:  WatchFiles detected changes in 'app/models/contact.py'. Reloading...
INFO:     Shutting down
INFO:     Waiting for application shutdown.
INFO:     Application shutdown complete.
INFO:     Finished server process [89177]
INFO:     Started server process [91867]
INFO:     Waiting for application startup.
INFO:     Application startup complete.
INFO:     127.0.0.1:61404 - "GET /api/contacts/ HTTP/1.1" 200 OK
INFO:     127.0.0.1:61498 - "GET /api/contacts/ HTTP/1.1" 200 OK
INFO:     127.0.0.1:61794 - "GET /api/contacts/ HTTP/1.1" 200 OK
WARNING:  WatchFiles detected changes in 'app/models/contact.py'. Reloading...
INFO:     Shutting down
INFO:     Waiting for application shutdown.
INFO:     Application shutdown complete.
INFO:     Finished server process [91867]
INFO:     Started server process [92176]
INFO:     Waiting for application startup.
INFO:     Application startup complete.
INFO:     127.0.0.1:63170 - "GET /api/contacts/ HTTP/1.1" 200 OK
INFO:     127.0.0.1:63362 - "GET /api/contacts/ HTTP/1.1" 200 OK
INFO:     127.0.0.1:63516 - "GET /api/contacts/ HTTP/1.1" 200 OK
INFO:     127.0.0.1:63818 - "GET /api/contacts/ HTTP/1.1" 200 OK
INFO:     127.0.0.1:65229 - "GET / HTTP/1.1" 200 OK
INFO:     127.0.0.1:65229 - "GET / HTTP/1.1" 200 OK
INFO:     127.0.0.1:65229 - "OPTIONS /api/contacts/ HTTP/1.1" 200 OK
INFO:     127.0.0.1:65229 - "GET /api/contacts/ HTTP/1.1" 200 OK
INFO:     127.0.0.1:65510 - "OPTIONS / HTTP/1.1" 200 OK
INFO:     127.0.0.1:65510 - "GET / HTTP/1.1" 200 OK
INFO:     127.0.0.1:51173 - "GET /api/contacts/ HTTP/1.1" 200 OK
INFO:     127.0.0.1:51241 - "OPTIONS / HTTP/1.1" 200 OK
INFO:     127.0.0.1:51243 - "OPTIONS / HTTP/1.1" 200 OK
INFO:     127.0.0.1:51241 - "GET / HTTP/1.1" 200 OK
INFO:     127.0.0.1:51241 - "GET / HTTP/1.1" 200 OK
INFO:     127.0.0.1:51241 - "GET /api/contacts/ HTTP/1.1" 200 OK
INFO:     127.0.0.1:51245 - "GET /api/contacts/ HTTP/1.1" 200 OK
INFO:     127.0.0.1:51952 - "GET /api/contacts/ HTTP/1.1" 200 OK
INFO:     127.0.0.1:53092 - "GET / HTTP/1.1" 200 OK
INFO:     127.0.0.1:53094 - "GET / HTTP/1.1" 200 OK
INFO:     127.0.0.1:53237 - "GET /api/contacts/ HTTP/1.1" 200 OK
INFO:     127.0.0.1:53316 - "GET / HTTP/1.1" 200 OK
INFO:     127.0.0.1:53316 - "GET / HTTP/1.1" 200 OK
INFO:     127.0.0.1:53316 - "GET /api/contacts/ HTTP/1.1" 200 OK
INFO:     127.0.0.1:56248 - "OPTIONS / HTTP/1.1" 200 OK
INFO:     127.0.0.1:56250 - "OPTIONS / HTTP/1.1" 200 OK
INFO:     127.0.0.1:56248 - "GET / HTTP/1.1" 200 OK
INFO:     127.0.0.1:56250 - "GET / HTTP/1.1" 200 OK
INFO:     127.0.0.1:56250 - "OPTIONS /api/contacts/ HTTP/1.1" 200 OK
INFO:     127.0.0.1:56250 - "GET /api/contacts/ HTTP/1.1" 200 OK
INFO:     127.0.0.1:60663 - "OPTIONS /api/contacts/ HTTP/1.1" 200 OK
INFO:     127.0.0.1:60663 - "GET /api/contacts/ HTTP/1.1" 200 OK
WARNING:  WatchFiles detected changes in 'app/models/organization.py'. Reloading...
INFO:     Shutting down
INFO:     Waiting for application shutdown.
INFO:     Application shutdown complete.
INFO:     Finished server process [92176]
WARNING:  WatchFiles detected changes in 'app/models/organization.py'. Reloading...
INFO:     Started server process [94211]
INFO:     Waiting for application startup.
INFO:     Application startup complete.
WARNING:  WatchFiles detected changes in 'app/controllers/organization_controller.py'. Reloading...
INFO:     Shutting down
INFO:     Waiting for application shutdown.
INFO:     Application shutdown complete.
INFO:     Finished server process [94211]
WARNING:  WatchFiles detected changes in 'app/controllers/organization_controller.py'. Reloading...
INFO:     Started server process [94249]
INFO:     Waiting for application startup.
INFO:     Application startup complete.
WARNING:  WatchFiles detected changes in 'app/controllers/organization_controller.py'. Reloading...
INFO:     Shutting down
INFO:     Waiting for application shutdown.
INFO:     Application shutdown complete.
INFO:     Finished server process [94249]
INFO:     Started server process [94257]
INFO:     Waiting for application startup.
INFO:     Application startup complete.
WARNING:  WatchFiles detected changes in 'app/models/database.py'. Reloading...
INFO:     Shutting down
INFO:     Waiting for application shutdown.
INFO:     Application shutdown complete.
INFO:     Finished server process [94257]
INFO:     Started server process [94298]
INFO:     Waiting for application startup.
INFO:     Application startup complete.
INFO:     127.0.0.1:64851 - "GET /api/contacts/ HTTP/1.1" 200 OK
WARNING:  WatchFiles detected changes in 'main.py'. Reloading...
INFO:     Shutting down
INFO:     Waiting for application shutdown.
INFO:     Application shutdown complete.
INFO:     Finished server process [94298]
Process SpawnProcess-11:
Traceback (most recent call last):
  File "/usr/local/Cellar/python@3.13/3.13.5/Frameworks/Python.framework/Versions/3.13/lib/python3.13/multiprocessing/process.py", line 313, in _bootstrap
    self.run()
    ~~~~~~~~^^
  File "/usr/local/Cellar/python@3.13/3.13.5/Frameworks/Python.framework/Versions/3.13/lib/python3.13/multiprocessing/process.py", line 108, in run
    self._target(*self._args, **self._kwargs)
    ~~~~~~~~~~~~^^^^^^^^^^^^^^^^^^^^^^^^^^^^^
  File "/Users/kgt/Desktop/Projects/new-trackon/backend/venv/lib/python3.13/site-packages/uvicorn/_subprocess.py", line 80, in subprocess_started
    target(sockets=sockets)
    ~~~~~~^^^^^^^^^^^^^^^^^
  File "/Users/kgt/Desktop/Projects/new-trackon/backend/venv/lib/python3.13/site-packages/uvicorn/server.py", line 67, in run
    return asyncio_run(self.serve(sockets=sockets), loop_factory=self.config.get_loop_factory())
  File "/usr/local/Cellar/python@3.13/3.13.5/Frameworks/Python.framework/Versions/3.13/lib/python3.13/asyncio/runners.py", line 195, in run
    return runner.run(main)
           ~~~~~~~~~~^^^^^^
  File "/usr/local/Cellar/python@3.13/3.13.5/Frameworks/Python.framework/Versions/3.13/lib/python3.13/asyncio/runners.py", line 118, in run
    return self._loop.run_until_complete(task)
           ~~~~~~~~~~~~~~~~~~~~~~~~~~~~~^^^^^^
  File "uvloop/loop.pyx", line 1518, in uvloop.loop.Loop.run_until_complete
  File "/Users/kgt/Desktop/Projects/new-trackon/backend/venv/lib/python3.13/site-packages/uvicorn/server.py", line 71, in serve
    await self._serve(sockets)
  File "/Users/kgt/Desktop/Projects/new-trackon/backend/venv/lib/python3.13/site-packages/uvicorn/server.py", line 78, in _serve
    config.load()
    ~~~~~~~~~~~^^
  File "/Users/kgt/Desktop/Projects/new-trackon/backend/venv/lib/python3.13/site-packages/uvicorn/config.py", line 438, in load
    self.loaded_app = import_from_string(self.app)
                      ~~~~~~~~~~~~~~~~~~^^^^^^^^^^
  File "/Users/kgt/Desktop/Projects/new-trackon/backend/venv/lib/python3.13/site-packages/uvicorn/importer.py", line 19, in import_from_string
    module = importlib.import_module(module_str)
  File "/usr/local/Cellar/python@3.13/3.13.5/Frameworks/Python.framework/Versions/3.13/lib/python3.13/importlib/__init__.py", line 88, in import_module
    return _bootstrap._gcd_import(name[level:], package, level)
           ~~~~~~~~~~~~~~~~~~~~~~^^^^^^^^^^^^^^^^^^^^^^^^^^^^^^
  File "<frozen importlib._bootstrap>", line 1387, in _gcd_import
  File "<frozen importlib._bootstrap>", line 1360, in _find_and_load
  File "<frozen importlib._bootstrap>", line 1331, in _find_and_load_unlocked
  File "<frozen importlib._bootstrap>", line 935, in _load_unlocked
  File "<frozen importlib._bootstrap_external>", line 1026, in exec_module
  File "<frozen importlib._bootstrap>", line 488, in _call_with_frames_removed
  File "/Users/kgt/Desktop/Projects/new-trackon/backend/main.py", line 17, in <module>
    from app.controllers.organization_controller import organization_router
ImportError: cannot import name 'organization_router' from 'app.controllers.organization_controller' (/Users/kgt/Desktop/Projects/new-trackon/backend/app/controllers/organization_controller.py)
WARNING:  WatchFiles detected changes in 'main.py'. Reloading...
Process SpawnProcess-12:
Traceback (most recent call last):
  File "/usr/local/Cellar/python@3.13/3.13.5/Frameworks/Python.framework/Versions/3.13/lib/python3.13/multiprocessing/process.py", line 313, in _bootstrap
    self.run()
    ~~~~~~~~^^
  File "/usr/local/Cellar/python@3.13/3.13.5/Frameworks/Python.framework/Versions/3.13/lib/python3.13/multiprocessing/process.py", line 108, in run
    self._target(*self._args, **self._kwargs)
    ~~~~~~~~~~~~^^^^^^^^^^^^^^^^^^^^^^^^^^^^^
  File "/Users/kgt/Desktop/Projects/new-trackon/backend/venv/lib/python3.13/site-packages/uvicorn/_subprocess.py", line 80, in subprocess_started
    target(sockets=sockets)
    ~~~~~~^^^^^^^^^^^^^^^^^
  File "/Users/kgt/Desktop/Projects/new-trackon/backend/venv/lib/python3.13/site-packages/uvicorn/server.py", line 67, in run
    return asyncio_run(self.serve(sockets=sockets), loop_factory=self.config.get_loop_factory())
  File "/usr/local/Cellar/python@3.13/3.13.5/Frameworks/Python.framework/Versions/3.13/lib/python3.13/asyncio/runners.py", line 195, in run
    return runner.run(main)
           ~~~~~~~~~~^^^^^^
  File "/usr/local/Cellar/python@3.13/3.13.5/Frameworks/Python.framework/Versions/3.13/lib/python3.13/asyncio/runners.py", line 118, in run
    return self._loop.run_until_complete(task)
           ~~~~~~~~~~~~~~~~~~~~~~~~~~~~~^^^^^^
  File "uvloop/loop.pyx", line 1518, in uvloop.loop.Loop.run_until_complete
  File "/Users/kgt/Desktop/Projects/new-trackon/backend/venv/lib/python3.13/site-packages/uvicorn/server.py", line 71, in serve
    await self._serve(sockets)
  File "/Users/kgt/Desktop/Projects/new-trackon/backend/venv/lib/python3.13/site-packages/uvicorn/server.py", line 78, in _serve
    config.load()
    ~~~~~~~~~~~^^
  File "/Users/kgt/Desktop/Projects/new-trackon/backend/venv/lib/python3.13/site-packages/uvicorn/config.py", line 438, in load
    self.loaded_app = import_from_string(self.app)
                      ~~~~~~~~~~~~~~~~~~^^^^^^^^^^
  File "/Users/kgt/Desktop/Projects/new-trackon/backend/venv/lib/python3.13/site-packages/uvicorn/importer.py", line 19, in import_from_string
    module = importlib.import_module(module_str)
  File "/usr/local/Cellar/python@3.13/3.13.5/Frameworks/Python.framework/Versions/3.13/lib/python3.13/importlib/__init__.py", line 88, in import_module
    return _bootstrap._gcd_import(name[level:], package, level)
           ~~~~~~~~~~~~~~~~~~~~~~^^^^^^^^^^^^^^^^^^^^^^^^^^^^^^
  File "<frozen importlib._bootstrap>", line 1387, in _gcd_import
  File "<frozen importlib._bootstrap>", line 1360, in _find_and_load
  File "<frozen importlib._bootstrap>", line 1331, in _find_and_load_unlocked
  File "<frozen importlib._bootstrap>", line 935, in _load_unlocked
  File "<frozen importlib._bootstrap_external>", line 1026, in exec_module
  File "<frozen importlib._bootstrap>", line 488, in _call_with_frames_removed
  File "/Users/kgt/Desktop/Projects/new-trackon/backend/main.py", line 17, in <module>
    from app.controllers.organization_controller import organization_router
ImportError: cannot import name 'organization_router' from 'app.controllers.organization_controller' (/Users/kgt/Desktop/Projects/new-trackon/backend/app/controllers/organization_controller.py)
WARNING:  WatchFiles detected changes in 'app/controllers/organization_controller.py'. Reloading...
Process SpawnProcess-13:
Traceback (most recent call last):
  File "/usr/local/Cellar/python@3.13/3.13.5/Frameworks/Python.framework/Versions/3.13/lib/python3.13/multiprocessing/process.py", line 313, in _bootstrap
    self.run()
    ~~~~~~~~^^
  File "/usr/local/Cellar/python@3.13/3.13.5/Frameworks/Python.framework/Versions/3.13/lib/python3.13/multiprocessing/process.py", line 108, in run
    self._target(*self._args, **self._kwargs)
    ~~~~~~~~~~~~^^^^^^^^^^^^^^^^^^^^^^^^^^^^^
  File "/Users/kgt/Desktop/Projects/new-trackon/backend/venv/lib/python3.13/site-packages/uvicorn/_subprocess.py", line 80, in subprocess_started
    target(sockets=sockets)
    ~~~~~~^^^^^^^^^^^^^^^^^
  File "/Users/kgt/Desktop/Projects/new-trackon/backend/venv/lib/python3.13/site-packages/uvicorn/server.py", line 67, in run
    return asyncio_run(self.serve(sockets=sockets), loop_factory=self.config.get_loop_factory())
  File "/usr/local/Cellar/python@3.13/3.13.5/Frameworks/Python.framework/Versions/3.13/lib/python3.13/asyncio/runners.py", line 195, in run
    return runner.run(main)
           ~~~~~~~~~~^^^^^^
  File "/usr/local/Cellar/python@3.13/3.13.5/Frameworks/Python.framework/Versions/3.13/lib/python3.13/asyncio/runners.py", line 118, in run
    return self._loop.run_until_complete(task)
           ~~~~~~~~~~~~~~~~~~~~~~~~~~~~~^^^^^^
  File "uvloop/loop.pyx", line 1518, in uvloop.loop.Loop.run_until_complete
  File "/Users/kgt/Desktop/Projects/new-trackon/backend/venv/lib/python3.13/site-packages/uvicorn/server.py", line 71, in serve
    await self._serve(sockets)
  File "/Users/kgt/Desktop/Projects/new-trackon/backend/venv/lib/python3.13/site-packages/uvicorn/server.py", line 78, in _serve
    config.load()
    ~~~~~~~~~~~^^
  File "/Users/kgt/Desktop/Projects/new-trackon/backend/venv/lib/python3.13/site-packages/uvicorn/config.py", line 438, in load
    self.loaded_app = import_from_string(self.app)
                      ~~~~~~~~~~~~~~~~~~^^^^^^^^^^
  File "/Users/kgt/Desktop/Projects/new-trackon/backend/venv/lib/python3.13/site-packages/uvicorn/importer.py", line 19, in import_from_string
    module = importlib.import_module(module_str)
  File "/usr/local/Cellar/python@3.13/3.13.5/Frameworks/Python.framework/Versions/3.13/lib/python3.13/importlib/__init__.py", line 88, in import_module
    return _bootstrap._gcd_import(name[level:], package, level)
           ~~~~~~~~~~~~~~~~~~~~~~^^^^^^^^^^^^^^^^^^^^^^^^^^^^^^
  File "<frozen importlib._bootstrap>", line 1387, in _gcd_import
  File "<frozen importlib._bootstrap>", line 1360, in _find_and_load
  File "<frozen importlib._bootstrap>", line 1331, in _find_and_load_unlocked
  File "<frozen importlib._bootstrap>", line 935, in _load_unlocked
  File "<frozen importlib._bootstrap_external>", line 1026, in exec_module
  File "<frozen importlib._bootstrap>", line 488, in _call_with_frames_removed
  File "/Users/kgt/Desktop/Projects/new-trackon/backend/main.py", line 17, in <module>
    from app.controllers.organization_controller import organization_router
  File "/Users/kgt/Desktop/Projects/new-trackon/backend/app/controllers/organization_controller.py", line 70, in <module>
    @router.post("/", response_model=OrganizationResponse)
     ^^^^^^
NameError: name 'router' is not defined
WARNING:  WatchFiles detected changes in 'app/controllers/organization_controller.py'. Reloading...
Process SpawnProcess-14:
Traceback (most recent call last):
  File "/usr/local/Cellar/python@3.13/3.13.5/Frameworks/Python.framework/Versions/3.13/lib/python3.13/multiprocessing/process.py", line 313, in _bootstrap
    self.run()
    ~~~~~~~~^^
  File "/usr/local/Cellar/python@3.13/3.13.5/Frameworks/Python.framework/Versions/3.13/lib/python3.13/multiprocessing/process.py", line 108, in run
    self._target(*self._args, **self._kwargs)
    ~~~~~~~~~~~~^^^^^^^^^^^^^^^^^^^^^^^^^^^^^
  File "/Users/kgt/Desktop/Projects/new-trackon/backend/venv/lib/python3.13/site-packages/uvicorn/_subprocess.py", line 80, in subprocess_started
    target(sockets=sockets)
    ~~~~~~^^^^^^^^^^^^^^^^^
  File "/Users/kgt/Desktop/Projects/new-trackon/backend/venv/lib/python3.13/site-packages/uvicorn/server.py", line 67, in run
    return asyncio_run(self.serve(sockets=sockets), loop_factory=self.config.get_loop_factory())
  File "/usr/local/Cellar/python@3.13/3.13.5/Frameworks/Python.framework/Versions/3.13/lib/python3.13/asyncio/runners.py", line 195, in run
    return runner.run(main)
           ~~~~~~~~~~^^^^^^
  File "/usr/local/Cellar/python@3.13/3.13.5/Frameworks/Python.framework/Versions/3.13/lib/python3.13/asyncio/runners.py", line 118, in run
    return self._loop.run_until_complete(task)
           ~~~~~~~~~~~~~~~~~~~~~~~~~~~~~^^^^^^
  File "uvloop/loop.pyx", line 1518, in uvloop.loop.Loop.run_until_complete
  File "/Users/kgt/Desktop/Projects/new-trackon/backend/venv/lib/python3.13/site-packages/uvicorn/server.py", line 71, in serve
    await self._serve(sockets)
  File "/Users/kgt/Desktop/Projects/new-trackon/backend/venv/lib/python3.13/site-packages/uvicorn/server.py", line 78, in _serve
    config.load()
    ~~~~~~~~~~~^^
  File "/Users/kgt/Desktop/Projects/new-trackon/backend/venv/lib/python3.13/site-packages/uvicorn/config.py", line 438, in load
    self.loaded_app = import_from_string(self.app)
                      ~~~~~~~~~~~~~~~~~~^^^^^^^^^^
  File "/Users/kgt/Desktop/Projects/new-trackon/backend/venv/lib/python3.13/site-packages/uvicorn/importer.py", line 19, in import_from_string
    module = importlib.import_module(module_str)
  File "/usr/local/Cellar/python@3.13/3.13.5/Frameworks/Python.framework/Versions/3.13/lib/python3.13/importlib/__init__.py", line 88, in import_module
    return _bootstrap._gcd_import(name[level:], package, level)
           ~~~~~~~~~~~~~~~~~~~~~~^^^^^^^^^^^^^^^^^^^^^^^^^^^^^^
  File "<frozen importlib._bootstrap>", line 1387, in _gcd_import
  File "<frozen importlib._bootstrap>", line 1360, in _find_and_load
  File "<frozen importlib._bootstrap>", line 1331, in _find_and_load_unlocked
  File "<frozen importlib._bootstrap>", line 935, in _load_unlocked
  File "<frozen importlib._bootstrap_external>", line 1026, in exec_module
  File "<frozen importlib._bootstrap>", line 488, in _call_with_frames_removed
  File "/Users/kgt/Desktop/Projects/new-trackon/backend/main.py", line 17, in <module>
    from app.controllers.organization_controller import organization_router
  File "/Users/kgt/Desktop/Projects/new-trackon/backend/app/controllers/organization_controller.py", line 81, in <module>
    @router.get("/", response_model=List[Organization])
     ^^^^^^
NameError: name 'router' is not defined
WARNING:  WatchFiles detected changes in 'app/controllers/organization_controller.py'. Reloading...
Process SpawnProcess-15:
Traceback (most recent call last):
  File "/usr/local/Cellar/python@3.13/3.13.5/Frameworks/Python.framework/Versions/3.13/lib/python3.13/multiprocessing/process.py", line 313, in _bootstrap
    self.run()
    ~~~~~~~~^^
  File "/usr/local/Cellar/python@3.13/3.13.5/Frameworks/Python.framework/Versions/3.13/lib/python3.13/multiprocessing/process.py", line 108, in run
    self._target(*self._args, **self._kwargs)
    ~~~~~~~~~~~~^^^^^^^^^^^^^^^^^^^^^^^^^^^^^
  File "/Users/kgt/Desktop/Projects/new-trackon/backend/venv/lib/python3.13/site-packages/uvicorn/_subprocess.py", line 80, in subprocess_started
    target(sockets=sockets)
    ~~~~~~^^^^^^^^^^^^^^^^^
  File "/Users/kgt/Desktop/Projects/new-trackon/backend/venv/lib/python3.13/site-packages/uvicorn/server.py", line 67, in run
    return asyncio_run(self.serve(sockets=sockets), loop_factory=self.config.get_loop_factory())
  File "/usr/local/Cellar/python@3.13/3.13.5/Frameworks/Python.framework/Versions/3.13/lib/python3.13/asyncio/runners.py", line 195, in run
    return runner.run(main)
           ~~~~~~~~~~^^^^^^
  File "/usr/local/Cellar/python@3.13/3.13.5/Frameworks/Python.framework/Versions/3.13/lib/python3.13/asyncio/runners.py", line 118, in run
    return self._loop.run_until_complete(task)
           ~~~~~~~~~~~~~~~~~~~~~~~~~~~~~^^^^^^
  File "uvloop/loop.pyx", line 1518, in uvloop.loop.Loop.run_until_complete
  File "/Users/kgt/Desktop/Projects/new-trackon/backend/venv/lib/python3.13/site-packages/uvicorn/server.py", line 71, in serve
    await self._serve(sockets)
  File "/Users/kgt/Desktop/Projects/new-trackon/backend/venv/lib/python3.13/site-packages/uvicorn/server.py", line 78, in _serve
    config.load()
    ~~~~~~~~~~~^^
  File "/Users/kgt/Desktop/Projects/new-trackon/backend/venv/lib/python3.13/site-packages/uvicorn/config.py", line 438, in load
    self.loaded_app = import_from_string(self.app)
                      ~~~~~~~~~~~~~~~~~~^^^^^^^^^^
  File "/Users/kgt/Desktop/Projects/new-trackon/backend/venv/lib/python3.13/site-packages/uvicorn/importer.py", line 19, in import_from_string
    module = importlib.import_module(module_str)
  File "/usr/local/Cellar/python@3.13/3.13.5/Frameworks/Python.framework/Versions/3.13/lib/python3.13/importlib/__init__.py", line 88, in import_module
    return _bootstrap._gcd_import(name[level:], package, level)
           ~~~~~~~~~~~~~~~~~~~~~~^^^^^^^^^^^^^^^^^^^^^^^^^^^^^^
  File "<frozen importlib._bootstrap>", line 1387, in _gcd_import
  File "<frozen importlib._bootstrap>", line 1360, in _find_and_load
  File "<frozen importlib._bootstrap>", line 1331, in _find_and_load_unlocked
  File "<frozen importlib._bootstrap>", line 935, in _load_unlocked
  File "<frozen importlib._bootstrap_external>", line 1026, in exec_module
  File "<frozen importlib._bootstrap>", line 488, in _call_with_frames_removed
  File "/Users/kgt/Desktop/Projects/new-trackon/backend/main.py", line 17, in <module>
    from app.controllers.organization_controller import organization_router
  File "/Users/kgt/Desktop/Projects/new-trackon/backend/app/controllers/organization_controller.py", line 114, in <module>
    @router.get("/{organization_id}", response_model=Organization)
     ^^^^^^
NameError: name 'router' is not defined
WARNING:  WatchFiles detected changes in 'app/controllers/organization_controller.py'. Reloading...
Process SpawnProcess-16:
Traceback (most recent call last):
  File "/usr/local/Cellar/python@3.13/3.13.5/Frameworks/Python.framework/Versions/3.13/lib/python3.13/multiprocessing/process.py", line 313, in _bootstrap
    self.run()
    ~~~~~~~~^^
  File "/usr/local/Cellar/python@3.13/3.13.5/Frameworks/Python.framework/Versions/3.13/lib/python3.13/multiprocessing/process.py", line 108, in run
    self._target(*self._args, **self._kwargs)
    ~~~~~~~~~~~~^^^^^^^^^^^^^^^^^^^^^^^^^^^^^
  File "/Users/kgt/Desktop/Projects/new-trackon/backend/venv/lib/python3.13/site-packages/uvicorn/_subprocess.py", line 80, in subprocess_started
    target(sockets=sockets)
    ~~~~~~^^^^^^^^^^^^^^^^^
  File "/Users/kgt/Desktop/Projects/new-trackon/backend/venv/lib/python3.13/site-packages/uvicorn/server.py", line 67, in run
    return asyncio_run(self.serve(sockets=sockets), loop_factory=self.config.get_loop_factory())
  File "/usr/local/Cellar/python@3.13/3.13.5/Frameworks/Python.framework/Versions/3.13/lib/python3.13/asyncio/runners.py", line 195, in run
    return runner.run(main)
           ~~~~~~~~~~^^^^^^
  File "/usr/local/Cellar/python@3.13/3.13.5/Frameworks/Python.framework/Versions/3.13/lib/python3.13/asyncio/runners.py", line 118, in run
    return self._loop.run_until_complete(task)
           ~~~~~~~~~~~~~~~~~~~~~~~~~~~~~^^^^^^
  File "uvloop/loop.pyx", line 1518, in uvloop.loop.Loop.run_until_complete
  File "/Users/kgt/Desktop/Projects/new-trackon/backend/venv/lib/python3.13/site-packages/uvicorn/server.py", line 71, in serve
    await self._serve(sockets)
  File "/Users/kgt/Desktop/Projects/new-trackon/backend/venv/lib/python3.13/site-packages/uvicorn/server.py", line 78, in _serve
    config.load()
    ~~~~~~~~~~~^^
  File "/Users/kgt/Desktop/Projects/new-trackon/backend/venv/lib/python3.13/site-packages/uvicorn/config.py", line 438, in load
    self.loaded_app = import_from_string(self.app)
                      ~~~~~~~~~~~~~~~~~~^^^^^^^^^^
  File "/Users/kgt/Desktop/Projects/new-trackon/backend/venv/lib/python3.13/site-packages/uvicorn/importer.py", line 19, in import_from_string
    module = importlib.import_module(module_str)
  File "/usr/local/Cellar/python@3.13/3.13.5/Frameworks/Python.framework/Versions/3.13/lib/python3.13/importlib/__init__.py", line 88, in import_module
    return _bootstrap._gcd_import(name[level:], package, level)
           ~~~~~~~~~~~~~~~~~~~~~~^^^^^^^^^^^^^^^^^^^^^^^^^^^^^^
  File "<frozen importlib._bootstrap>", line 1387, in _gcd_import
  File "<frozen importlib._bootstrap>", line 1360, in _find_and_load
  File "<frozen importlib._bootstrap>", line 1331, in _find_and_load_unlocked
  File "<frozen importlib._bootstrap>", line 935, in _load_unlocked
  File "<frozen importlib._bootstrap_external>", line 1026, in exec_module
  File "<frozen importlib._bootstrap>", line 488, in _call_with_frames_removed
  File "/Users/kgt/Desktop/Projects/new-trackon/backend/main.py", line 17, in <module>
    from app.controllers.organization_controller import organization_router
  File "/Users/kgt/Desktop/Projects/new-trackon/backend/app/controllers/organization_controller.py", line 132, in <module>
    @router.put("/{organization_id}", response_model=OrganizationResponse)
     ^^^^^^
NameError: name 'router' is not defined
WARNING:  WatchFiles detected changes in 'app/controllers/organization_controller.py'. Reloading...
Process SpawnProcess-17:
Traceback (most recent call last):
  File "/usr/local/Cellar/python@3.13/3.13.5/Frameworks/Python.framework/Versions/3.13/lib/python3.13/multiprocessing/process.py", line 313, in _bootstrap
    self.run()
    ~~~~~~~~^^
  File "/usr/local/Cellar/python@3.13/3.13.5/Frameworks/Python.framework/Versions/3.13/lib/python3.13/multiprocessing/process.py", line 108, in run
    self._target(*self._args, **self._kwargs)
    ~~~~~~~~~~~~^^^^^^^^^^^^^^^^^^^^^^^^^^^^^
  File "/Users/kgt/Desktop/Projects/new-trackon/backend/venv/lib/python3.13/site-packages/uvicorn/_subprocess.py", line 80, in subprocess_started
    target(sockets=sockets)
    ~~~~~~^^^^^^^^^^^^^^^^^
  File "/Users/kgt/Desktop/Projects/new-trackon/backend/venv/lib/python3.13/site-packages/uvicorn/server.py", line 67, in run
    return asyncio_run(self.serve(sockets=sockets), loop_factory=self.config.get_loop_factory())
  File "/usr/local/Cellar/python@3.13/3.13.5/Frameworks/Python.framework/Versions/3.13/lib/python3.13/asyncio/runners.py", line 195, in run
    return runner.run(main)
           ~~~~~~~~~~^^^^^^
  File "/usr/local/Cellar/python@3.13/3.13.5/Frameworks/Python.framework/Versions/3.13/lib/python3.13/asyncio/runners.py", line 118, in run
    return self._loop.run_until_complete(task)
           ~~~~~~~~~~~~~~~~~~~~~~~~~~~~~^^^^^^
  File "uvloop/loop.pyx", line 1518, in uvloop.loop.Loop.run_until_complete
  File "/Users/kgt/Desktop/Projects/new-trackon/backend/venv/lib/python3.13/site-packages/uvicorn/server.py", line 71, in serve
    await self._serve(sockets)
  File "/Users/kgt/Desktop/Projects/new-trackon/backend/venv/lib/python3.13/site-packages/uvicorn/server.py", line 78, in _serve
    config.load()
    ~~~~~~~~~~~^^
  File "/Users/kgt/Desktop/Projects/new-trackon/backend/venv/lib/python3.13/site-packages/uvicorn/config.py", line 438, in load
    self.loaded_app = import_from_string(self.app)
                      ~~~~~~~~~~~~~~~~~~^^^^^^^^^^
  File "/Users/kgt/Desktop/Projects/new-trackon/backend/venv/lib/python3.13/site-packages/uvicorn/importer.py", line 19, in import_from_string
    module = importlib.import_module(module_str)
  File "/usr/local/Cellar/python@3.13/3.13.5/Frameworks/Python.framework/Versions/3.13/lib/python3.13/importlib/__init__.py", line 88, in import_module
    return _bootstrap._gcd_import(name[level:], package, level)
           ~~~~~~~~~~~~~~~~~~~~~~^^^^^^^^^^^^^^^^^^^^^^^^^^^^^^
  File "<frozen importlib._bootstrap>", line 1387, in _gcd_import
  File "<frozen importlib._bootstrap>", line 1360, in _find_and_load
  File "<frozen importlib._bootstrap>", line 1331, in _find_and_load_unlocked
  File "<frozen importlib._bootstrap>", line 935, in _load_unlocked
  File "<frozen importlib._bootstrap_external>", line 1026, in exec_module
  File "<frozen importlib._bootstrap>", line 488, in _call_with_frames_removed
  File "/Users/kgt/Desktop/Projects/new-trackon/backend/main.py", line 17, in <module>
    from app.controllers.organization_controller import organization_router
  File "/Users/kgt/Desktop/Projects/new-trackon/backend/app/controllers/organization_controller.py", line 156, in <module>
    @router.delete("/{organization_id}", response_model=OrganizationResponse)
     ^^^^^^
NameError: name 'router' is not defined
WARNING:  WatchFiles detected changes in 'app/controllers/organization_controller.py'. Reloading...
Process SpawnProcess-18:
Traceback (most recent call last):
  File "/usr/local/Cellar/python@3.13/3.13.5/Frameworks/Python.framework/Versions/3.13/lib/python3.13/multiprocessing/process.py", line 313, in _bootstrap
    self.run()
    ~~~~~~~~^^
  File "/usr/local/Cellar/python@3.13/3.13.5/Frameworks/Python.framework/Versions/3.13/lib/python3.13/multiprocessing/process.py", line 108, in run
    self._target(*self._args, **self._kwargs)
    ~~~~~~~~~~~~^^^^^^^^^^^^^^^^^^^^^^^^^^^^^
  File "/Users/kgt/Desktop/Projects/new-trackon/backend/venv/lib/python3.13/site-packages/uvicorn/_subprocess.py", line 80, in subprocess_started
    target(sockets=sockets)
    ~~~~~~^^^^^^^^^^^^^^^^^
  File "/Users/kgt/Desktop/Projects/new-trackon/backend/venv/lib/python3.13/site-packages/uvicorn/server.py", line 67, in run
    return asyncio_run(self.serve(sockets=sockets), loop_factory=self.config.get_loop_factory())
  File "/usr/local/Cellar/python@3.13/3.13.5/Frameworks/Python.framework/Versions/3.13/lib/python3.13/asyncio/runners.py", line 195, in run
    return runner.run(main)
           ~~~~~~~~~~^^^^^^
  File "/usr/local/Cellar/python@3.13/3.13.5/Frameworks/Python.framework/Versions/3.13/lib/python3.13/asyncio/runners.py", line 118, in run
    return self._loop.run_until_complete(task)
           ~~~~~~~~~~~~~~~~~~~~~~~~~~~~~^^^^^^
  File "uvloop/loop.pyx", line 1518, in uvloop.loop.Loop.run_until_complete
  File "/Users/kgt/Desktop/Projects/new-trackon/backend/venv/lib/python3.13/site-packages/uvicorn/server.py", line 71, in serve
    await self._serve(sockets)
  File "/Users/kgt/Desktop/Projects/new-trackon/backend/venv/lib/python3.13/site-packages/uvicorn/server.py", line 78, in _serve
    config.load()
    ~~~~~~~~~~~^^
  File "/Users/kgt/Desktop/Projects/new-trackon/backend/venv/lib/python3.13/site-packages/uvicorn/config.py", line 438, in load
    self.loaded_app = import_from_string(self.app)
                      ~~~~~~~~~~~~~~~~~~^^^^^^^^^^
  File "/Users/kgt/Desktop/Projects/new-trackon/backend/venv/lib/python3.13/site-packages/uvicorn/importer.py", line 19, in import_from_string
    module = importlib.import_module(module_str)
  File "/usr/local/Cellar/python@3.13/3.13.5/Frameworks/Python.framework/Versions/3.13/lib/python3.13/importlib/__init__.py", line 88, in import_module
    return _bootstrap._gcd_import(name[level:], package, level)
           ~~~~~~~~~~~~~~~~~~~~~~^^^^^^^^^^^^^^^^^^^^^^^^^^^^^^
  File "<frozen importlib._bootstrap>", line 1387, in _gcd_import
  File "<frozen importlib._bootstrap>", line 1360, in _find_and_load
  File "<frozen importlib._bootstrap>", line 1331, in _find_and_load_unlocked
  File "<frozen importlib._bootstrap>", line 935, in _load_unlocked
  File "<frozen importlib._bootstrap_external>", line 1026, in exec_module
  File "<frozen importlib._bootstrap>", line 488, in _call_with_frames_removed
  File "/Users/kgt/Desktop/Projects/new-trackon/backend/main.py", line 17, in <module>
    from app.controllers.organization_controller import organization_router
  File "/Users/kgt/Desktop/Projects/new-trackon/backend/app/controllers/organization_controller.py", line 175, in <module>
    @router.get("/search/by-name", response_model=List[Organization])
     ^^^^^^
NameError: name 'router' is not defined
WARNING:  WatchFiles detected changes in 'app/controllers/organization_controller.py'. Reloading...
INFO:     Started server process [95075]
INFO:     Waiting for application startup.
INFO:     Application startup complete.
INFO:     127.0.0.1:50135 - "OPTIONS / HTTP/1.1" 200 OK
INFO:     127.0.0.1:50139 - "OPTIONS / HTTP/1.1" 200 OK
INFO:     127.0.0.1:50459 - "OPTIONS / HTTP/1.1" 200 OK
INFO:     127.0.0.1:50461 - "OPTIONS / HTTP/1.1" 200 OK
INFO:     127.0.0.1:50504 - "OPTIONS / HTTP/1.1" 200 OK
INFO:     127.0.0.1:50505 - "OPTIONS / HTTP/1.1" 200 OK
INFO:     127.0.0.1:50638 - "OPTIONS / HTTP/1.1" 200 OK
INFO:     127.0.0.1:54050 - "OPTIONS / HTTP/1.1" 200 OK
INFO:     127.0.0.1:54052 - "OPTIONS / HTTP/1.1" 200 OK
INFO:     127.0.0.1:54054 - "OPTIONS / HTTP/1.1" 200 OK
INFO:     127.0.0.1:54056 - "OPTIONS / HTTP/1.1" 200 OK
INFO:     127.0.0.1:54058 - "OPTIONS / HTTP/1.1" 200 OK
INFO:     127.0.0.1:54060 - "GET / HTTP/1.1" 200 OK
INFO:     127.0.0.1:54050 - "GET / HTTP/1.1" 200 OK
INFO:     127.0.0.1:54050 - "GET / HTTP/1.1" 200 OK
INFO:     127.0.0.1:54050 - "GET / HTTP/1.1" 200 OK
INFO:     127.0.0.1:54050 - "GET / HTTP/1.1" 200 OK
WARNING:  WatchFiles detected changes in 'app/models/database.py', 'main.py'. Reloading...
INFO:     Shutting down
INFO:     Waiting for application shutdown.
INFO:     Application shutdown complete.
INFO:     Finished server process [95075]
Fatal Python error: init_sys_streams: can't initialize sys standard streams
Python runtime state: core initialized
OSError: [Errno 9] Bad file descriptor

Current thread 0x00007ff845ff7f80 (most recent call first):
  <no Python frame>
WARNING:  WatchFiles detected changes in 'app/controllers/organization_controller.py', 'app/models/database.py', 'main.py', 'app/models/organization.py'. Reloading...
Fatal Python error: init_sys_streams: can't initialize sys standard streams
Python runtime state: core initialized
OSError: [Errno 9] Bad file descriptor

Current thread 0x00007ff845ff7f80 (most recent call first):
  <no Python frame>
